Exception in thread Thread-1:
Traceback (most recent call last):
  File "/home/paolo/NAS/Software/roboGarden/server/blueprints/threads.py", line 65, in read_from_port
    data_str = ser.readline(ser.in_waiting + 100)
  File "/home/paolo/NAS/Software/roboGarden/server/.venv/lib/python3.8/site-packages/serial/serialposix.py", line 595, in read
    raise SerialException(
serial.serialutil.SerialException: device reports readiness to read but returned no data (device disconnected or multiple access on port?)

During handling of the above exception, another exception occurred:

Traceback (most recent call last):
  File "/usr/lib/python3.8/threading.py", line 932, in _bootstrap_inner
    self.run()
  File "/usr/lib/python3.8/threading.py", line 870, in run
    self._target(*self._args, **self._kwargs)
  File "/home/paolo/NAS/Software/roboGarden/server/blueprints/threads.py", line 69, in read_from_port
    except_counter += 1
UnboundLocalError: local variable 'except_counter' referenced before assignment



https://stackoverflow.com/questions/17553543/pyserial-non-blocking-read-loop
https://github.com/pyserial/pyserial/issues/86
https://github.com/pyserial/pyserial/issues/216#issuecomment-369414522
https://stackoverflow.com/questions/39111502/python-pyserial-threading
